Workbook

Sheet README
A1: FDC Limited — potential supplier & backup-supplier database
A2: Compiled 16 October 2026 from public sources (company sites, catalogues, associations, exhibitor lists, annual reports, rating rationales, regulator pages, public trade-record summaries). No paid databases.
A4: What this is
A5: Purpose | B5: Long list of POTENTIAL suppliers and backup suppliers for FDC Limited across six materials. Every company is a potential supplier only: no qualification, audit, sample approval or existing FDC relationship is implied or claimed.
A6: Status | B6: Interim version. The public web-search and page-reading tools were rate-limited during compilation, so most records rest on search-result titles and URLs rather than pages read in full. Research continues; see 'Coverage gaps' below.
A7: How to use the workbook
A8: Companies | B8: One row per deduplicated legal entity, with every material category it supports. Group affiliates in other countries (e.g. Bericap India vs BERICAP GmbH) are kept as separate entities.
A9: Category sheets | B9: One row per company x category ('supplier line'), sorted by subcategory, then pharma/ORS relevance, region (India first: West, North, South, Central, East, Northeast, Pan-India, then International) and evidence confidence.
A10: All Supplier Lines | B10: Every supplier line in one filterable table; the Summary sheet counts from here.
A11: Sources | B11: One row per source URL per supplier line, hyperlinked.
A12: Category definitions and separations
A13: Dextrose / glucose | B13: Crystalline dextrose (anhydrous / monohydrate). Pharma grades (IP/BP/USP/EP, pyrogen-free, CEP/DMF) and food grades are separated by subcategory. Liquid glucose / glucose syrup, maltodextrin, fructose and sorbitol are recorded only in 'Related products kept separate'. Starch processors with no crystalline dextrose found are kept as upstream/backup with their own subcategory.
A14: Corn / maize | B14: Upstream input to starch and dextrose. Wet-millers, bulk traders/aggregators, FPCs, platforms and procurement agencies. Seed-only, sweet-corn, popcorn and snack businesses excluded. FDC is not assumed to buy maize directly.
A15: PET resin | B15: Bottle-grade and film-grade separated; virgin resin manufacture separated from recycling (food-grade bottle-to-bottle vs non-food) and from distribution. Food-contact status is recorded as 'claimed' unless a regulator source was read.
A16: PET bottles and preforms | B16: Subcategory states preforms only, bottles only, or both. HDPE/PP/LDPE lines are noted under 'Related products kept separate'. Sizes, neck finishes and plant locations are captured where a source gave them.
A17: Caps and closures | B17: Screw, tamper-evident, child-resistant, dispensing and ROPP closures, plus liners/induction seals. Caps are not assumed to be PET; materials are recorded only where a source stated them.
A18: BOPET base film vs laminate converters | B18: The Polyester/BOPET category is split: 'BOPET Base Film' holds base-film makers, metallizers/coaters and film distributors; 'Laminate Converters' holds printers/laminators making sachets, pouches and rollstock. BOPP, CPP, PE film, foil and cartons are noted separately where relevant.
A19: Column notes
A20: Legal name verified | B20: Yes = registered name seen on a company page, filing, rating rationale or registry page. No = trade name only; confirm on MCA (India) or the local registry before contracting.
A21: Evidence confidence | B21: High = company's own page read and confirms the product. Medium = company-domain result, annual report, rating rationale, association/exhibitor listing or reputable trade press. Low = third-party B2B listing or a single weak source.
A22: Priority match (keyword-derived) | B22: Automatic flag from the recorded applications / grades / notes text: 'Pharma / ORS', 'Nutrition / food / beverage' or 'Not stated in sources'. It is a sorting aid, not a qualification.
A23: Capacity, revenue, rating, ownership | B23: Filled only where a public source gave them; blank means not found, not zero.
A24: Caveats before RFQ
A25: Verification | B25: Before shortlisting: confirm grade certificates (CoA, pharmacopoeial compliance, DMF/CEP letters of access), food-contact declarations (EU 10/2011, US FDA, FSSAI/BIS), ISO 15378 / FSSC 22000 certificates, and plant audits. Low-confidence B2B entries may be traders rather than manufacturers.
A26: Sources | B26: Public sources only: company sites, B2B storefronts, trade press, exhibitor listings, rating-agency pages, regulator pages and registry summaries. No paid databases were used.

Sheet Summary
A1: Coverage summary (counts recalculate from the 'All Supplier Lines' sheet)
A3: Segment | B3: India-West | C3: India-North | D3: India-South | E3: India-Central | F3: India-East | G3: India-Northeast | H3: India-Pan | I3: International | J3: Total
A4: Dextrose/Glucose | B4: =COUNTIFS('All Supplier Lines'!$F$2:$F$107,$A4,'All Supplier Lines'!$N$2:$N$107,B$3) -> 4 | C4: =COUNTIFS('All Supplier Lines'!$F$2:$F$107,$A4,'All Supplier Lines'!$N$2:$N$107,C$3) -> 1 | D4: =COUNTIFS('All Supplier Lines'!$F$2:$F$107,$A4,'All Supplier Lines'!$N$2:$N$107,D$3) -> 0 | E4: =COUNTIFS('All Supplier Lines'!$F$2:$F$107,$A4,'All Supplier Lines'!$N$2:$N$107,E$3) -> 0 | F4: =COUNTIFS('All Supplier Lines'!$F$2:$F$107,$A4,'All Supplier Lines'!$N$2:$N$107,F$3) -> 1 | G4: =COUNTIFS('All Supplier Lines'!$F$2:$F$107,$A4,'All Supplier Lines'!$N$2:$N$107,G$3) -> 0 | H4: =COUNTIFS('All Supplier Lines'!$F$2:$F$107,$A4,'All Supplier Lines'!$N$2:$N$107,H$3) -> 4 | I4: =COUNTIFS('All Supplier Lines'!$F$2:$F$107,$A4,'All Supplier Lines'!$N$2:$N$107,I$3) -> 27 | J4: =SUM(B4:I4) -> 37
A5: Corn/Maize | B5: =COUNTIFS('All Supplier Lines'!$F$2:$F$107,$A5,'All Supplier Lines'!$N$2:$N$107,B$3) -> 5 | C5: =COUNTIFS('All Supplier Lines'!$F$2:$F$107,$A5,'All Supplier Lines'!$N$2:$N$107,C$3) -> 3 | D5: =COUNTIFS('All Supplier Lines'!$F$2:$F$107,$A5,'All Supplier Lines'!$N$2:$N$107,D$3) -> 1 | E5: =COUNTIFS('All Supplier Lines'!$F$2:$F$107,$A5,'All Supplier Lines'!$N$2:$N$107,E$3) -> 1 | F5: =COUNTIFS('All Supplier Lines'!$F$2:$F$107,$A5,'All Supplier Lines'!$N$2:$N$107,F$3) -> 1 | G5: =COUNTIFS('All Supplier Lines'!$F$2:$F$107,$A5,'All Supplier Lines'!$N$2:$N$107,G$3) -> 0 | H5: =COUNTIFS('All Supplier Lines'!$F$2:$F$107,$A5,'All Supplier Lines'!$N$2:$N$107,H$3) -> 2 | I5: =COUNTIFS('All Supplier Lines'!$F$2:$F$107,$A5,'All Supplier Lines'!$N$2:$N$107,I$3) -> 0 | J5: =SUM(B5:I5) -> 13
A6: PET Resin | B6: =COUNTIFS('All Supplier Lines'!$F$2:$F$107,$A6,'All Supplier Lines'!$N$2:$N$107,B$3) -> 1 | C6: =COUNTIFS('All Supplier Lines'!$F$2:$F$107,$A6,'All Supplier Lines'!$N$2:$N$107,C$3) -> 0 | D6: =COUNTIFS('All Supplier Lines'!$F$2:$F$107,$A6,'All Supplier Lines'!$N$2:$N$107,D$3) -> 1 | E6: =COUNTIFS('All Supplier Lines'!$F$2:$F$107,$A6,'All Supplier Lines'!$N$2:$N$107,E$3) -> 0 | F6: =COUNTIFS('All Supplier Lines'!$F$2:$F$107,$A6,'All Supplier Lines'!$N$2:$N$107,F$3) -> 1 | G6: =COUNTIFS('All Supplier Lines'!$F$2:$F$107,$A6,'All Supplier Lines'!$N$2:$N$107,G$3) -> 0 | H6: =COUNTIFS('All Supplier Lines'!$F$2:$F$107,$A6,'All Supplier Lines'!$N$2:$N$107,H$3) -> 3 | I6: =COUNTIFS('All Supplier Lines'!$F$2:$F$107,$A6,'All Supplier Lines'!$N$2:$N$107,I$3) -> 1 | J6: =SUM(B6:I6) -> 7
A7: PET Bottles & Preforms | B7: =COUNTIFS('All Supplier Lines'!$F$2:$F$107,$A7,'All Supplier Lines'!$N$2:$N$107,B$3) -> 8 | C7: =COUNTIFS('All Supplier Lines'!$F$2:$F$107,$A7,'All Supplier Lines'!$N$2:$N$107,C$3) -> 1 | D7: =COUNTIFS('All Supplier Lines'!$F$2:$F$107,$A7,'All Supplier Lines'!$N$2:$N$107,D$3) -> 6 | E7: =COUNTIFS('All Supplier Lines'!$F$2:$F$107,$A7,'All Supplier Lines'!$N$2:$N$107,E$3) -> 0 | F7: =COUNTIFS('All Supplier Lines'!$F$2:$F$107,$A7,'All Supplier Lines'!$N$2:$N$107,F$3) -> 1 | G7: =COUNTIFS('All Supplier Lines'!$F$2:$F$107,$A7,'All Supplier Lines'!$N$2:$N$107,G$3) -> 0 | H7: =COUNTIFS('All Supplier Lines'!$F$2:$F$107,$A7,'All Supplier Lines'!$N$2:$N$107,H$3) -> 2 | I7: =COUNTIFS('All Supplier Lines'!$F$2:$F$107,$A7,'All Supplier Lines'!$N$2:$N$107,I$3) -> 1 | J7: =SUM(B7:I7) -> 19
A8: Caps & Closures | B8: =COUNTIFS('All Supplier Lines'!$F$2:$F$107,$A8,'All Supplier Lines'!$N$2:$N$107,B$3) -> 2 | C8: =COUNTIFS('All Supplier Lines'!$F$2:$F$107,$A8,'All Supplier Lines'!$N$2:$N$107,C$3) -> 0 | D8: =COUNTIFS('All Supplier Lines'!$F$2:$F$107,$A8,'All Supplier Lines'!$N$2:$N$107,D$3) -> 0 | E8: =COUNTIFS('All Supplier Lines'!$F$2:$F$107,$A8,'All Supplier Lines'!$N$2:$N$107,E$3) -> 0 | F8: =COUNTIFS('All Supplier Lines'!$F$2:$F$107,$A8,'All Supplier Lines'!$N$2:$N$107,F$3) -> 0 | G8: =COUNTIFS('All Supplier Lines'!$F$2:$F$107,$A8,'All Supplier Lines'!$N$2:$N$107,G$3) -> 0 | H8: =COUNTIFS('All Supplier Lines'!$F$2:$F$107,$A8,'All Supplier Lines'!$N$2:$N$107,H$3) -> 4 | I8: =COUNTIFS('All Supplier Lines'!$F$2:$F$107,$A8,'All Supplier Lines'!$N$2:$N$107,I$3) -> 13 | J8: =SUM(B8:I8) -> 19
A9: BOPET base film | B9: =COUNTIFS('All Supplier Lines'!$F$2:$F$107,$A9,'All Supplier Lines'!$N$2:$N$107,B$3) -> 1 | C9: =COUNTIFS('All Supplier Lines'!$F$2:$F$107,$A9,'All Supplier Lines'!$N$2:$N$107,C$3) -> 1 | D9: =COUNTIFS('All Supplier Lines'!$F$2:$F$107,$A9,'All Supplier Lines'!$N$2:$N$107,D$3) -> 0 | E9: =COUNTIFS('All Supplier Lines'!$F$2:$F$107,$A9,'All Supplier Lines'!$N$2:$N$107,E$3) -> 1 | F9: =COUNTIFS('All Supplier Lines'!$F$2:$F$107,$A9,'All Supplier Lines'!$N$2:$N$107,F$3) -> 0 | G9: =COUNTIFS('All Supplier Lines'!$F$2:$F$107,$A9,'All Supplier Lines'!$N$2:$N$107,G$3) -> 0 | H9: =COUNTIFS('All Supplier Lines'!$F$2:$F$107,$A9,'All Supplier Lines'!$N$2:$N$107,H$3) -> 2 | I9: =COUNTIFS('All Supplier Lines'!$F$2:$F$107,$A9,'All Supplier Lines'!$N$2:$N$107,I$3) -> 2 | J9: =SUM(B9:I9) -> 7
A10: Laminate converters | B10: =COUNTIFS('All Supplier Lines'!$F$2:$F$107,$A10,'All Supplier Lines'!$N$2:$N$107,B$3) -> 2 | C10: =COUNTIFS('All Supplier Lines'!$F$2:$F$107,$A10,'All Supplier Lines'!$N$2:$N$107,C$3) -> 1 | D10: =COUNTIFS('All Supplier Lines'!$F$2:$F$107,$A10,'All Supplier Lines'!$N$2:$N$107,D$3) -> 0 | E10: =COUNTIFS('All Supplier Lines'!$F$2:$F$107,$A10,'All Supplier Lines'!$N$2:$N$107,E$3) -> 0 | F10: =COUNTIFS('All Supplier Lines'!$F$2:$F$107,$A10,'All Supplier Lines'!$N$2:$N$107,F$3) -> 0 | G10: =COUNTIFS('All Supplier Lines'!$F$2:$F$107,$A10,'All Supplier Lines'!$N$2:$N$107,G$3) -> 0 | H10: =COUNTIFS('All Supplier Lines'!$F$2:$F$107,$A10,'All Supplier Lines'!$N$2:$N$107,H$3) -> 1 | I10: =COUNTIFS('All Supplier Lines'!$F$2:$F$107,$A10,'All Supplier Lines'!$N$2:$N$107,I$3) -> 0 | J10: =SUM(B10:I10) -> 4
A11: Total supplier lines | B11: =SUM(B4:B10) -> 23 | C11: =SUM(C4:C10) -> 7 | D11: =SUM(D4:D10) -> 8 | E11: =SUM(E4:E10) -> 2 | F11: =SUM(F4:F10) -> 4 | G11: =SUM(G4:G10) -> 0 | H11: =SUM(H4:H10) -> 18 | I11: =SUM(I4:I10) -> 44 | J11: =SUM(J4:J10) -> 106
A13: By evidence confidence / priority match
A14: Segment | B14: High | C14: Medium | D14: Low | E14: Pharma / ORS | F14: Nutrition / food / beverage | G14: Not stated in sources
A15: Dextrose/Glucose | B15: =COUNTIFS('All Supplier Lines'!$F$2:$F$107,$A15,'All Supplier Lines'!$Y$2:$Y$107,B$14) -> 3 | C15: =COUNTIFS('All Supplier Lines'!$F$2:$F$107,$A15,'All Supplier Lines'!$Y$2:$Y$107,C$14) -> 18 | D15: =COUNTIFS('All Supplier Lines'!$F$2:$F$107,$A15,'All Supplier Lines'!$Y$2:$Y$107,D$14) -> 16 | E15: =COUNTIFS('All Supplier Lines'!$F$2:$F$107,$A15,'All Supplier Lines'!$M$2:$M$107,E$14) -> 28 | F15: =COUNTIFS('All Supplier Lines'!$F$2:$F$107,$A15,'All Supplier Lines'!$M$2:$M$107,F$14) -> 5 | G15: =COUNTIFS('All Supplier Lines'!$F$2:$F$107,$A15,'All Supplier Lines'!$M$2:$M$107,G$14) -> 4
A16: Corn/Maize | B16: =COUNTIFS('All Supplier Lines'!$F$2:$F$107,$A16,'All Supplier Lines'!$Y$2:$Y$107,B$14) -> 1 | C16: =COUNTIFS('All Supplier Lines'!$F$2:$F$107,$A16,'All Supplier Lines'!$Y$2:$Y$107,C$14) -> 9 | D16: =COUNTIFS('All Supplier Lines'!$F$2:$F$107,$A16,'All Supplier Lines'!$Y$2:$Y$107,D$14) -> 3 | E16: =COUNTIFS('All Supplier Lines'!$F$2:$F$107,$A16,'All Supplier Lines'!$M$2:$M$107,E$14) -> 0 | F16: =COUNTIFS('All Supplier Lines'!$F$2:$F$107,$A16,'All Supplier Lines'!$M$2:$M$107,F$14) -> 0 | G16: =COUNTIFS('All Supplier Lines'!$F$2:$F$107,$A16,'All Supplier Lines'!$M$2:$M$107,G$14) -> 0
A17: PET Resin | B17: =COUNTIFS('All Supplier Lines'!$F$2:$F$107,$A17,'All Supplier Lines'!$Y$2:$Y$107,B$14) -> 0 | C17: =COUNTIFS('All Supplier Lines'!$F$2:$F$107,$A17,'All Supplier Lines'!$Y$2:$Y$107,C$14) -> 6 | D17: =COUNTIFS('All Supplier Lines'!$F$2:$F$107,$A17,'All Supplier Lines'!$Y$2:$Y$107,D$14) -> 1 | E17: =COUNTIFS('All Supplier Lines'!$F$2:$F$107,$A17,'All Supplier Lines'!$M$2:$M$107,E$14) -> 1 | F17: =COUNTIFS('All Supplier Lines'!$F$2:$F$107,$A17,'All Supplier Lines'!$M$2:$M$107,F$14) -> 6 | G17: =COUNTIFS('All Supplier Lines'!$F$2:$F$107,$A17,'All Supplier Lines'!$M$2:$M$107,G$14) -> 0
A18: PET Bottles & Preforms | B18: =COUNTIFS('All Supplier Lines'!$F$2:$F$107,$A18,'All Supplier Lines'!$Y$2:$Y$107,B$14) -> 0 | C18: =COUNTIFS('All Supplier Lines'!$F$2:$F$107,$A18,'All Supplier Lines'!$Y$2:$Y$107,C$14) -> 5 | D18: =COUNTIFS('All Supplier Lines'!$F$2:$F$107,$A18,'All Supplier Lines'!$Y$2:$Y$107,D$14) -> 14 | E18: =COUNTIFS('All Supplier Lines'!$F$2:$F$107,$A18,'All Supplier Lines'!$M$2:$M$107,E$14) -> 12 | F18: =COUNTIFS('All Supplier Lines'!$F$2:$F$107,$A18,'All Supplier Lines'!$M$2:$M$107,F$14) -> 2 | G18: =COUNTIFS('All Supplier Lines'!$F$2:$F$107,$A18,'All Supplier Lines'!$M$2:$M$107,G$14) -> 5
A19: Caps & Closures | B19: =COUNTIFS('All Supplier Lines'!$F$2:$F$107,$A19,'All Supplier Lines'!$Y$2:$Y$107,B$14) -> 0 | C19: =COUNTIFS('All Supplier Lines'!$F$2:$F$107,$A19,'All Supplier Lines'!$Y$2:$Y$107,C$14) -> 13 | D19: =COUNTIFS('All Supplier Lines'!$F$2:$F$107,$A19,'All Supplier Lines'!$Y$2:$Y$107,D$14) -> 6 | E19: =COUNTIFS('All Supplier Lines'!$F$2:$F$107,$A19,'All Supplier Lines'!$M$2:$M$107,E$14) -> 18 | F19: =COUNTIFS('All Supplier Lines'!$F$2:$F$107,$A19,'All Supplier Lines'!$M$2:$M$107,F$14) -> 0 | G19: =COUNTIFS('All Supplier Lines'!$F$2:$F$107,$A19,'All Supplier Lines'!$M$2:$M$107,G$14) -> 1
A20: BOPET base film | B20: =COUNTIFS('All Supplier Lines'!$F$2:$F$107,$A20,'All Supplier Lines'!$Y$2:$Y$107,B$14) -> 0 | C20: =COUNTIFS('All Supplier Lines'!$F$2:$F$107,$A20,'All Supplier Lines'!$Y$2:$Y$107,C$14) -> 7 | D20: =COUNTIFS('All Supplier Lines'!$F$2:$F$107,$A20,'All Supplier Lines'!$Y$2:$Y$107,D$14) -> 0 | E20: =COUNTIFS('All Supplier Lines'!$F$2:$F$107,$A20,'All Supplier Lines'!$M$2:$M$107,E$14) -> 1 | F20: =COUNTIFS('All Supplier Lines'!$F$2:$F$107,$A20,'All Supplier Lines'!$M$2:$M$107,F$14) -> 6 | G20: =COUNTIFS('All Supplier Lines'!$F$2:$F$107,$A20,'All Supplier Lines'!$M$2:$M$107,G$14) -> 0
A21: Laminate converters | B21: =COUNTIFS('All Supplier Lines'!$F$2:$F$107,$A21,'All Supplier Lines'!$Y$2:$Y$107,B$14) -> 0 | C21: =COUNTIFS('All Supplier Lines'!$F$2:$F$107,$A21,'All Supplier Lines'!$Y$2:$Y$107,C$14) -> 4 | D21: =COUNTIFS('All Supplier Lines'!$F$2:$F$107,$A21,'All Supplier Lines'!$Y$2:$Y$107,D$14) -> 0 | E21: =COUNTIFS('All Supplier Lines'!$F$2:$F$107,$A21,'All Supplier Lines'!$M$2:$M$107,E$14) -> 4 | F21: =COUNTIFS('All Supplier Lines'!$F$2:$F$107,$A21,'All Supplier Lines'!$M$2:$M$107,F$14) -> 0 | G21: =COUNTIFS('All Supplier Lines'!$F$2:$F$107,$A21,'All Supplier Lines'!$M$2:$M$107,G$14) -> 0
A23: Unique companies | B23: =COUNTA(Companies!$A$2:$A$98) -> 97
A24: Companies in 2+ categories | B24: =COUNTIF(Companies!$J$2:$J$98,">1") -> 9
A25: Source links (all lines) | B25: =COUNTA(Sources!$D$2:$D$323) -> 322
A27: Note: 'Priority match' is a keyword flag from the recorded applications/grades/notes text, not a qualification. Maize rows are counted as upstream inputs.

Sheet Companies
A1: Company ID | B1: Company (legal / registered name) | C1: Trade / brand name | D1: Legal name verified | E1: Website | F1: HQ | G1: Country | H1: Region | I1: Material categories supported | J1: No. of categories | K1: Roles | L1: Ownership | M1: Capacity (published) | N1: Revenue (published) | O1: Credit rating | P1: Certifications (as stated) | Q1: Best evidence confidence | R1: No. of sources | S1: Sources
A2: C0001 | B2: Ahimsa Industries Limited | C2: Ahimsa Industries | D2: No | G2: India | H2: India-West | I2: PET Bottles & Preforms | J2: 1 | K2: Manufacturer (claims, unverified) | Q2: Low | R2: 2 | S2: https://www.dial4trade.com/ahimsa-industries/pet-preforms-pdid-744484.htm https://petpla.net/wikipetia/index.php/Ahmisa_Industries_Limited
A3: C0002 | B3: Amcor (India operations; registered entity not verified) | C3: Amcor India | D3: No | E3: https://www.amcor.com | F3: India | G3: India | H3: India-Pan | I3: Laminate converters | J3: 1 | K3: Converter | L3: MNC subsidiary - Amcor group; acquired Phoenix Flexibles (Packaging Gateway headline) | Q3: Medium | R3: 4 | S3: https://packagingsouthasia.com/packaging-production/amcor-india-opens-seventh-plant-in-india-at-bharuch https://www.packaging-gateway.com/news/amcor-acquire-phoenix-flexibles/ https://esmmagazine.com/packaging-design/amcor-acquires-flexible-packaging-plant-in-india-247427 https://www.petnology.com/online/news-detail/amcor-announces-acquisition-of-scalable-flexible-packaging-plant-in-high-growth-indian-market
A4: C0003 | B4: Apollo Healthcare Resources | D4: No | F4: Singapore | G4: Singapore | H4: International | I4: Dextrose/Glucose | J4: 1 | K4: Distributor | P4: GMP, CEP, USDMF, JDMF, KDMF, WC, EDMF/ASMF, FDA, ISO 9001, BSE/TSE (as listed on PharmaOffer; not verified) | Q4: Low | R4: 1 | S4: https://pharmaoffer.com/api-excipient-supplier/dextrose-anhydrate/cep
A5: C0004 | B5: Aptar Pharma India Private Limited | C5: Aptar Pharma | D5: No | E5: https://aptar.com | F5: Mumbai, Maharashtra, India | G5: India | H5: India-West | I5: Caps & Closures | J5: 1 | K5: Manufacturer | L5: MNC subsidiary of AptarGroup Inc. (NYSE: ATR) | Q5: Medium | R5: 3 | S5: https://m.indiamart.com/aptar/aboutus.html https://www.indianpharmapost.com/news/aptar-expands-mumbai-operations-as-it-adds-local-production-of-pharma-inhalation-tech-22137 https://www.packaginginsights.com/news/aptar-pharma-expands-presence-in-india.html
A6: C0005 | B6: AptarGroup, Inc. | C6: Aptar Pharma | D6: No | E6: https://www.aptar.com | F6: Crystal Lake, Illinois, USA | G6: USA | H6: International | I6: Caps & Closures | J6: 1 | K6: Manufacturer | L6: Listed (NYSE: ATR) | Q6: Low | R6: 1 | S6: https://www.aptar.com/pharmaceutical/technologies/child-resistant-senior-friendly/
A7: C0006 | B7: Archer-Daniels-Midland Company | C7: ADM (CLINTOSE®) | D7: No | E7: https://www.adm.com | F7: Chicago, Illinois, USA | G7: USA | H7: International | I7: Dextrose/Glucose | J7: 1 | K7: Manufacturer | L7: Listed – NYSE: ADM (general knowledge) | Q7: Medium | R7: 3 | S7: https://www.tilleydistributionproducts.com/products/clintose-dextrose-a https://tilleydistributionproducts.com/products/clintose-dextrose-vf https://knowde.com/stores/adm/products/adm-dextrose-monohydrate
A8: C0007 | B8: Arshine Pharmaceutical Co., Limited | C8: Arshine | D8: No | F8: China | G8: China | H8: International | I8: Dextrose/Glucose | J8: 1 | K8: Distributor; Exporter | P8: GMP, CEP, USDMF, EDMF/ASMF, FDA, BSE/TSE (as listed on PharmaOffer; not verified) | Q8: Low | R8: 1 | S8: https://pharmaoffer.com/api-excipient-supplier/dextrose-anhydrate/cep
A9: C0008 | B9: Avantor, Inc. | C9: VWR / J.T.Baker® / Macron Fine Chemicals™ | D9: No | E9: https://www.avantorsciences.com | F9: Pennsylvania, USA | G9: USA | H9: International | I9: Dextrose/Glucose | J9: 1 | K9: Supplier/repackager (J.T.Baker brand); Distributor (VWR) | L9: Listed – NYSE: AVTR (general knowledge) | Q9: Medium | R9: 4 | S9: https://b2b-ca.vwr.com/store/product/en/4541456/dextrose-anhydrous-97-5-102-0-by-anhydrous-basis-usp-multi-compendial-j-t-baker https://b2b-us.vwr.com/store/product/4541456/null https://b2b-cn.vwr.com/store/product/8030185/null https://www.avantorsciences.com/pt/en/search/USLP070318BIOP00008
A10: C0009 | B10: BERICAP GmbH & Co. KG | C10: Bericap | D10: No | E10: https://bericap.com | F10: Budenheim, Germany | G10: Germany | H10: International | I10: Caps & Closures | J10: 1 | K10: Manufacturer | L10: Private | Q10: Medium | R10: 3 | S10: https://bericap.com/home-care-pharma-supplies/landingpage-otc-pharmaceuticals/ https://www.packaging-gateway.com/products/bericap-closure-solutions-home-care-pharma-supplies/ https://packagingeurope.com/bericap-presents-closure-solutions-at-packaging-innovations/5782.article
A11: C0010 | B11: Bericap India Private Limited | C11: BERICAP | D11: Yes | E11: https://bericap.com | F11: Pune, Maharashtra, India (RoC Pune per CIN) | G11: India | H11: India-West | I11: Caps & Closures | J11: 1 | K11: Manufacturer | L11: MNC subsidiary of BERICAP GmbH & Co. KG (Germany); former JV with Essel Propack, Bericap acquired Essel's stake | M11: Trade press (Aug 2018) reported Bericap doubling its India plant; figure not captured | Q11: Medium | R11: 4 | S11: https://www.InstaFinancials.com/company/bericap-india-private-limited/U25202PN2001PTC140929 https://www.plasticsnews.com/article/20180828/NEWS/180829902/bericap-doubling-india-plant/ https://www.plastemart.com/news-plastics-information/bericap-to-acquire-essel-propack´s-share-in-indian-jv/8930 https://bericap.com/product/hc-ev-28-27-pco-1881/
A12: C0011 | B12: Berlin Packaging | C12: Berlin Packaging EU | D12: No | E12: https://berlinpackaging.eu | F12: Chicago, Illinois, USA | G12: USA | H12: International | I12: Caps & Closures | J12: 1 | K12: Distributor | Q12: Low | R12: 1 | S12: https://berlinpackaging.eu/en-be/markets/healthcare/packaging/child-resistant-closures
A13: C0012 | B13: Berry Global, Inc. | C13: Berry Global Healthcare | D13: No | E13: https://www.berryglobal.com | F13: Evansville, Indiana, USA | G13: USA | H13: International | I13: Caps & Closures | J13: 1 | K13: Manufacturer | L13: Berry Global Group, Inc. (SEC registrant, CIK 1378992). Berry agreed a merger with Amcor in 2024-25; current ownership status not verified in this session. | Q13: Medium | R13: 5 | S13: https://www.berryglobal.com/en/product/product-item/13191479 https://www.berryglobal.com/en/product/product-item/13567185 https://packagingeurope.com/news/berry-global-offers-range-of-pet-bottle-and-closure-solutions-for-child-safe-and-tamper-evident-medicine-packaging/9429.article https://packagingscotland.com/2023/02/berry-group-healthcare-launches-comprehensive-new-child-resistant-range/ https://www.sec.gov/Archives/edgar/data/0001378992/000137899218000039/form10k.htm
A14: C0013 | B14: Biesterfeld AG | C14: Biesterfeld | D14: No | E14: https://www.biesterfeld.com | F14: Hamburg, Germany | G14: Germany | H14: International | I14: Dextrose/Glucose | J14: 1 | K14: Distributor | Q14: Medium | R14: 2 | S14: https://www.biesterfeld.com/en/gb/product/dextrose-glucose https://www.biesterfeld.com/en/at/product/dextrose-glucose/
A15: C0014 | B15: Cargill S.L.U. | C15: Cargill | D15: No | E15: https://www.cargill.com/pharmaceutical/pharma-products/glucose-monohydrates-dextrose | F15: Spain | G15: Spain | H15: International | I15: Dextrose/Glucose | J15: 1 | K15: Manufacturer | L15: Subsidiary of Cargill, Incorporated (USA, private) | P15: CEP (glucose monohydrate), FDA, CoA – as listed on PharmaOffer (third-party listing) | Q15: Medium | R15: 5 | S15: https://pharmaoffer.com/api-excipient-supplier/excipients/glucose-monohydrate/cep https://pharmaoffer.com/api-excipient-supplier/glucose-monohydrate/cep https://www.cargill.com/pharmaceutical/pharma-products/glucose-monohydrates-dextrose https://www.cargill.com/products/pharmaceutical/products/glucose-monohydrates/ https://pharmacompass.com/ndc-api/cargill-slu
A16: C0015 | B16: Cargill, Incorporated | C16: Cargill (C*Dex) | D16: No | E16: https://www.cargill.com | F16: Minnesota, USA | G16: USA | H16: International | I16: Dextrose/Glucose | J16: 1 | K16: Manufacturer | L16: Private (general knowledge) | Q16: Medium | R16: 2 | S16: https://www.cargill.com/food-bev/emea/c-dex-dextrose https://www.cargill.com/food-bev/ap/dextrose
A17: C0016 | B17: Chemco Plastic Industries | C17: Chemco Group | Chemco | D17: No | E17: https://www.chemcogroup.com | G17: India | H17: India-West | I17: PET Bottles & Preforms; PET Resin | J17: 2 | K17: Manufacturer; Recycler | Recycler | L17: Private group (Chemco Group) | P17: FSSAI approval for food-grade rPET (trade press headline 'Chemco gets FSSAI nod') | Q17: Medium | R17: 7 | S17: https://www.packaginginsights.com/news/chemco-pet-bottle-recycling-india.html https://www.plastemart.com/news-plastics-information/chemco-group-pioneering-circularity-with-in-house-rpet-production/75112 https://www.industrialautomationindia.in/news/chemco-group-food-grade-rpet-facility-sanand https://themachinemaker.com/news/chemco-group-launches-%e2%82%b9125-crore-food-grade-rpet-bottle-recycling-plant-in-gujarat/ https://packagingsouthasia.com/type-of-article/industry-news/chemco-gets-fssai-nod/ https://m.indiamart.com/chemcoplastic https://www.packaging-gateway.com/news/chemco-gujarat-rpet-recycling-plant/
A18: C0017 | B18: Chr. Olesen | C18: Chr. Olesen | D18: No | F18: Denmark | G18: Denmark | H18: International | I18: Dextrose/Glucose | J18: 1 | K18: Distributor | P18: FDA, USDMF, CoA listed; Eurofins GMP audit report Sep 2023 (PharmaOffer listing) | Q18: Low | R18: 2 | S18: https://pharmaoffer.com/api-excipient-supplier/excipients/glucose-monohydrate/cep https://pharmaoffer.com/api-excipient-supplier/glucose-monohydrate/cep
A19: C0018 | B19: Closure Systems International | C19: CSI | D19: No | H19: International | I19: Caps & Closures | J19: 1 | K19: Manufacturer | Q19: Medium | R19: 3 | S19: https://www.packaginginsights.com/news/closure-systems-international-child-resistant-closure.html https://www.silicon.co.uk/press-release/closure-systems-international-launches-defender-lok-crc-product-line https://finance.yahoo.com/news/closure-systems-international-introduces-child-142709276.html
A20: C0019 | B20: Comar | C20: Comar | D20: No | G20: USA | H20: International | I20: Caps & Closures | J20: 1 | K20: Manufacturer | Q20: Medium | R20: 3 | S20: https://www.healthcarepackaging.com/industries/pharmaceuticals/press-release/13287374/comar-childresistant-closures https://app.qualifyze.com/directory/supplier/comar-71f904da https://directory.designnews.com/comar-inc-comp225738.html
A21: C0020 | B21: Constantia Flexibles (India operations; registered entity not verified) | C21: Constantia Flexibles | D21: No | E21: https://cflex.com | F21: Ahmedabad, Gujarat, India | G21: India | H21: India-West | I21: Laminate converters | J21: 1 | K21: Converter | L21: MNC subsidiary - Constantia Flexibles group | Q21: Medium | R21: 6 | S21: https://cflex.com/newsroom/constantia-flexibles-to-expand-production-capacity-in-india https://www.printweek.in/News/constantia-flexibles-invest-rs-100-crore-ahmedabad-plant-28024 https://packagingsouthasia.com/packaging-production/constantia-flexibles-to-invest-inr-100-crore-in-a-new-india-plant/ https://www.dcatvci.org/?p=6358 https://www.packaging-gateway.com/news/constantia-flexibles-expand-production-capacity-indian-facility/ https://www.packaging-gateway.com/projects/parikhpackagingfacil/
A22: C0021 | B22: Cosmos (Grupo Cosmos) | C22: Cosmos | D22: No | E22: https://www.cosmos.com.mx | F22: Mexico | G22: Mexico | H22: International | I22: Dextrose/Glucose | J22: 1 | K22: Distributor | Q22: Medium | R22: 1 | S22: https://www.cosmos.com.mx/producto/dextrosa-4bfp/dextrosa-anhidra-d7jd/dextrosa-anhidra-grado-farmaceutico-ddbs/
A23: C0022 | B23: Crystal Polymers | D23: No | E23: https://m.indiamart.com/crystal-poly/ | G23: India | H23: India-South | I23: PET Bottles & Preforms | J23: 1 | K23: Manufacturer (claimed on B2B listing; not verified) | Q23: Low | R23: 1 | S23: https://m.indiamart.com/crystal-poly/profile.html
A24: C0023 | B24: CSPC Shengxue Glucose Co., Ltd. | C24: CSPC Shengxue (石药圣雪) | D24: No | F24: Hebei, China | G24: China | H24: International | I24: Dextrose/Glucose | J24: 1 | K24: Manufacturer | L24: CSPC group company (CSPC Pharmaceutical Group is HKEX-listed, 1093 – general knowledge; current shareholding not verified) | P24: US DMF (PharmaCompass listing) | Q24: Medium | R24: 3 | S24: https://pharmacompass.com/us-drug-master-files-dmfs/anhydrous-dextrose https://www.pharmacompass.com/about/cspc-shengxue-glucose https://doc.irasia.com/listco/hk/cspc/annual/2018/screspress.pdf
A25: C0024 | B25: Dalmia Polypro Industries Private Limited | C25: Dalmia Polypro | D25: No | G25: India | H25: India-Pan | I25: PET Resin | J25: 1 | K25: Recycler | L25: Private; investee of Circulate Capital (2020); raising USD 30 mn from US DFC | Q25: Medium | R25: 5 | S25: https://www.erema.com/en/public-relations-news/dalmia-polypro-to-install-erema-systems-for-pet-und-fuer-po-recycling--3233/ https://packagingsouthasia.com/application/dalmia-polypros-food-grade/ https://www.outlookbusiness.com/news/dalmia-polypro-to-raise-usd-30-mn-from-us-dfc-to-build-facility-in-maharashtra https://www.circulatecapital.com/wp-content/uploads/2022/12/DalmiaPolyproIndustriesPL-x-CC_-Press-Release_2020-12-10-.pdf https://www.packaging-gateway.com/news/slmg-dalmia-india-plant/
A26: C0025 | B26: Drug Plastics & Glass Company, Inc. | C26: Drug Plastics | D26: Yes | G26: USA | H26: International | I26: Caps & Closures | J26: 1 | K26: Manufacturer | Q26: Low | R26: 3 | S26: https://trademarks.justia.com/owners/drug-plastics-glass-company-inc-135913 https://www.pharmaceutical-tech.com/suppliers/drug-plastics-glass-co-inc https://niemagazine.com/resources/sourcebook/6455/drug-plastics-glass-co-inc/
A27: C0026 | B27: EICL Limited | C27: Bharat Starch Industries (starch division); 'Haathi' brand | D27: Yes | E27: https://eicl.in | F27: Gurugram, Haryana, India (office listed on company site) | G27: India | H27: India-North | I27: Corn/Maize | J27: 1 | K27: Processor (starch wet-miller); Manufacturer | L27: Thapar Group lineage; Indian Starch & Chemicals Ltd (1937), later renamed Bharat Starch Industries Ltd, became part of EICL in 2001 (company page) | M27: 80,000 MTPA starch processing base, multi-feedstock (company page, dated (c)2015) | Q27: Medium | R27: 2 | S27: https://eicl.in/?p=284 https://eicl.in/?p=572
A28: C0027 | B28: Elchemy | C28: Elchemy | D28: No | E28: https://elchemy.com/ | F28: India | G28: India | H28: India-Pan | I28: Dextrose/Glucose | J28: 1 | K28: Distributor; Marketplace/platform | L28: Private | Q28: Low | R28: 1 | S28: https://elchemy.com/product/dextrose-monohydrate-1509
A29: C0028 | B29: Ester Industries Limited | C29: Ester | D29: Yes | E29: https://www.esterindustries.com | G29: India | H29: India-Pan | I29: BOPET base film | J29: 1 | K29: Manufacturer | L29: Listed (NSE: ESTER) | O29: CRISIL - rationales dated 13 May 2024 and 22 Jul 2025 (rating level not read this run) | Q29: Medium | R29: 2 | S29: https://www.crisil.com/mnt/winshare/Ratings/RatingList/RatingDocs/EsterIndustriesLimited_July 22_ 2025_RR_374336.html https://www.crisil.com/mnt/winshare/Ratings/RatingList/RatingDocs/EsterIndustriesLimited_May 13_ 2024_RR_343559.html
A30: C0029 | B30: Ganesha Ecosphere Limited | C30: GO Rewise | D30: No | G30: India | H30: India-Pan | I30: PET Resin | J30: 1 | K30: Recycler; Manufacturer | L30: Listed (NSE: GANECOS) | Q30: Medium | R30: 4 | S30: https://nsearchives.nseindia.com/corporate/GANECOS_03092025232921_annual_report.pdf https://recyclinginside.com/news/bottle-to-fibre-and-bottle-to-bottle-two-starlinger-pet-recycling-lines-for-indian-recycling-brand-go-rewise/ https://www.wasterecyclingmag.com/news/plastic-recycling/bottle-to-fibre-and-bottle-to-bottle-two-starlinger-pet-recycling-lines-for-indian-recycling-brand-go-rewise https://www.innovationintextiles.com/trailblazing-pet-recycling-in-india
A31: C0030 | B31: Garware Hi-Tech Films Limited | C31: Garware | D31: Yes | E31: https://www.garwarehitechfilms.com | G31: India | H31: India-West | I31: BOPET base film | J31: 1 | K31: Manufacturer | L31: Listed (NSE: GRWRHITECH) | Q31: Medium | R31: 2 | S31: https://machinist.in/2025/09/garware-hi-tech-films-starts-commercial-production-of-new-ppf-line-at-waluj-facility/ https://www.garwarehitechfilms.com/wp-content/uploads/2023/03/Investors-Presentation-May-2021.pdf.pdf
A32: C0031 | B32: Gerresheimer (India operations) | C32: Gerresheimer | D32: No | E32: https://www.gerresheimer.com | F32: Düsseldorf, Germany (India operations) | G32: Germany | H32: India-Pan | I32: Caps & Closures | J32: 1 | K32: Manufacturer | L32: MNC; Gerresheimer AG (listed, Frankfurt) | Q32: Medium | R32: 1 | S32: https://gerresheimer.com/en/company/newsroom/corporate-news/detail/cphi-india-gerresheimer-customers-value-child-resistant-pharmaceutical-packaging-1
A33: C0032 | B33: Global Closure Systems | C33: GCS | D33: No | H33: International | I33: Caps & Closures | J33: 1 | K33: Manufacturer | Q33: Medium | R33: 4 | S33: https://manufacturingchemist.com/global-closure-systems-gcs-launches-pharmasafe-child-resistant-closure-91334 https://www.healthcarepackaging.com/home/press-release/13290585/global-closure-systems-exhibits-at-pharmapack-europe-2016 https://pharmtech.com/view/global-closure-systems-exhibits-cphi-2015 https://www.plasteurope.com/news/GLOBAL_CLOSURE_SYSTEMS_t228478
A34: C0033 | B34: Guala Closures S.p.A. | C34: Guala Closures | D34: Yes | E34: https://www.gualaclosures.com | F34: Alessandria, Italy | G34: Italy | H34: International | I34: Caps & Closures | J34: 1 | K34: Manufacturer | Q34: Medium | R34: 4 | S34: https://www.gualaclosures.com/pharma https://www.gualaclosures.com/sites/default/files/files/allegati/2025-10/PR%20-%20GUALA%20CLOSURES%20ENTERS%20INTO%20PHARMACEUTICAL%20CLOSURES%20MARKET%20_%20Final.pdf https://www.gualaclosures.com/guala-closures-pharmapack-kwk-strengthening-its-presence-pharmaceutical-sector https://www.wolftheiss.com/insights/wolf-theiss-advises-guala-closures-s-p-a-on-the-acquisition-of-austrian-packaging-company-kunststoffwerk-kremsmunster-gmbh/
A35: C0034 | B35: Gujarat Ambuja Exports Limited | C35: GAEL / Ambuja Group | D35: Yes | E35: https://www.ambujagroup.com/ | F35: Ahmedabad, Gujarat, India | G35: India | H35: India-West | I35: Corn/Maize; Dextrose/Glucose | J35: 2 | K35: Manufacturer; Processor (maize wet-miller) | Processor (maize wet-miller); Manufacturer | L35: Listed (NSE: GAEL; BSE) | Listed (NSE: GAEL; BSE: 524226) | M35: New 1,200 TPD maize processing unit commenced commercial production Mar-2025 (NSE filing title); group total not verified this session | O35: CARE press releases Jan-2025, Aug-2025, Sep-2025, Dec-2025 and CRISIL rationales Apr-2023 exist; ratings not read (fetch rate-limited) | P35: Certificates page exists on company site (contents not read) | Q35: High | R35: 7 | S35: https://www.ambujagroup.com/ https://www.ambujagroup.com/starch-derivatives https://www.ambujagroup.com/dextrose-anhydrous-powder https://www.ambujagroup.com/dextrose-monohydrate-powder https://www.wrightresearch.in/stocks/stock/GAEL/ https://nsearchives.nseindia.com/corporate/GAEL_26032025100331_Commercial_Production_1200TPD_Maize.pdf https://www.careratings.com/upload/CompanyFiles/PR/202512121257_Gujarat_Ambuja_Exports_Limited.pdf
A36: C0035 | B36: Gulshan Polyols Limited | C36: Gulshan Polyols | D36: Yes | G36: India | H36: India-North | I36: Corn/Maize | J36: 1 | K36: Processor (starch wet-miller); Manufacturer | L36: Listed (BSE: 532457) | M36: 300 TPD corn grinding (UP); planned 1,000 TPD maize grinding (Bihar); ethanol 560 KLPD+ total (Assam 500 KLPD added June 2024) | Q36: Medium | R36: 3 | S36: https://www.indiainfoline.com/company/gulshan-polyols-ltd/summary https://www.gurufocus.com/stock/BOM:532457/transcripts/8616616 https://www.plindia.com/stocks/gulshan-polyols-ltd/
A37: C0036 | B37: Harsh Impex | D37: No | F37: Odisha, India | G37: India | H37: India-East | I37: PET Bottles & Preforms | J37: 1 | K37: Claims manufacturer (B2B listing only; plant not verified) | Q37: Low | R37: 3 | S37: https://www.globallinker.com/products/trusted-pet-preform-manufacturers-in-odisha-harsh-impex-best-price-8457231 https://www.globallinker.com/seller/harsh-impex https://yourstory.com/companies/harsh-impex
A38: C0037 | B38: Hawkins, Inc. | C38: Hawkins | D38: No | E38: https://www.hawkinsinc.com | F38: Minnesota, USA | G38: USA | H38: International | I38: Dextrose/Glucose | J38: 1 | K38: Distributor (page titled 'Dextrose Manufacturer, Supplier & Distributor'; own dextrose production not verified) | L38: Listed – NASDAQ: HWKN (general knowledge) | Q38: Medium | R38: 1 | S38: https://www.hawkinsinc.com/groups/pharmaceutical/dextrose/
A39: C0038 | B39: Hitesh Plastics | C39: Hitesh Plastics | D39: No | F39: India (location not verified this session) | G39: India | H39: India-West; India-Pan | I39: Caps & Closures; PET Bottles & Preforms | J39: 2 | K39: Manufacturer | L39: Acquired by Manjushree Technopack (Advent International-backed), 2022 | Acquired by Manjushree Technopack Ltd (Advent International-backed), Aug 2022 per petpla.net/PrintWeek | Q39: Medium | R39: 6 | S39: https://news.ventureintelligence.com/ma/manjushree-technopack-to-acquire-caps-maker-hitesh-plastics https://www.printweek.in/News/manjushree-technopack-backed-by-advent-to-acquire-hitesh-plastics-56469 https://www.petnology.com/online/news-detail/manjushree-technopack-acquires-hitesh-plastics https://www.printweek.in/news/manjushree-technopack-backed-by-advent-to-acquire-hitesh-plastics-56469 https://petpla.net/2022/08/08/manjushree-technopack-acquires-hitesh-plastics/ https://packagingsouthasia.com/type-of-article/manjushree-technopack-plant/
A40: C0039 | B40: Huhtamaki India Limited | C40: Huhtamaki India (formerly Huhtamaki PPL) | D40: No | E40: https://www.huhtamaki.com/en/flexible-packaging/about-us/india/ | F40: Thane, Maharashtra, India | G40: India | H40: India-West | I40: Laminate converters | J40: 1 | K40: Converter | L40: Listed in India (NSE: HUHTAMAKI per Morningstar listing URL); part of the Huhtamaki group (company India page on huhtamaki.com) | Q40: Medium | R40: 5 | S40: https://www.huhtamaki.com/en/flexible-packaging/about-us/india/ https://www.plastemart.com/news-plastics-information/huhtamaki-india-limited-a-leading-flexible-packaging-converter-for-fmcg-and-food-brands/75108 https://en.wikipedia.org/wiki/Huhtamaki_PPL https://dfd.dr.morningstar.com.au/investments/security/NSE/HUHTAMAKI https://production.huhtamaki.com/en-in/flexible-packaging
...

Sheet Dextrose
A1: Dextrose — 37 supplier lines. Crystalline dextrose only; liquid glucose, maltodextrin and fructose are listed under 'Related products kept separate'.
A2: Company ID | B2: Company (legal / registered name) | C2: Trade / brand name | D2: Legal name verified | E2: Subcategory | F2: Relevant products | G2: Grades / specs / sizes / materials | H2: Related products kept separate (out of scope) | I2: Role | J2: Applications | K2: Priority match (keyword-derived) | L2: Region | M2: HQ | N2: Country | O2: Plants | P2: Website | Q2: Certifications (as stated) | R2: Capacity (published) | S2: Revenue (published) | T2: Ownership | U2: Credit rating | V2: Suitability / verification notes | W2: Evidence confidence | X2: Also listed under | Y2: No. of sources | Z2: Sources
A3: C0073 | B3: Roquette India Private Limited | C3: Roquette India (formerly Roquette Riddhi Siddhi) | D3: No | E3: Dextrose – pharma grade | F3: Roquette group: LYCADEX PF (dextrose monohydrate, pyrogen-free); LYCADEX BioPharma (dextrose monohydrate, low endotoxin); GLUCIDEX 21 dehydrated glucose syrup listed as an India product | G3: Dextrose monohydrate pyrogen-free / low-endotoxin (group pharma range). Whether LYCADEX is produced in India or imported not verified. | H3: GLUCIDEX maltodextrin/dehydrated glucose syrup; starches; polyols | I3: Manufacturer (starch derivatives in India); MNC subsidiary; Importer/marketer of group pharma excipients (inferred – verify) | J3: Pharma (parenteral/oral), biopharma cell culture, food | K3: Pharma / ORS | L3: India-Pan | M3: India | N3: India | O3: Pantnagar (Uttarakhand) and Viramgam (Gujarat) per Roquette press releases; other Indian sites of the former Riddhi Siddhi corn wet-milling business not verified here | P3: https://www.roquette.com/ | T3: Subsidiary of Roquette Frères (France); Roquette took over the Riddhi Siddhi Gluco Biols corn wet-milling business (strategic partner 2005-06, business demerged 2009-10, Roquette asset acquisition reported 2012) | V3: Strong pharma-dextrose pedigree at group level (LYCADEX PF pyrogen-free). Indian manufacture of crystalline dextrose not verified in this pass; Riddhi Siddhi's historic timeline shows dextrose monohydrate capacity before the demerger. Confirm with Roquette India whether pharma dextrose is supplied from Indian plants or imported. | W3: Medium | X3: Corn/Maize | Y3: 8 | Z3: https://www.roquette.com/pharma-lycadex-pf-dextrose-monohydrate-pyrogen-free https://www.roquette.com/health-pharma/biologics-product-finder/lycadex-biopharma-dextrose-monohydrate-low-endotoxin https://www.roquette.com/health-pharma/pharmaceutical-product-catalog/glucidex-21-dehydrated-glucose-syrup-india https://www.roquette.com/press-releases/product-capabilities-viramgam-india https://www.roquette.com/press-releases/roquette-celebrates-10-years-operation-pantnagar https://www.indianchemicalnews.com/general/lite/roquette-inaugurates-spray-tower-at-pantnagar-site-in-india-11507 https://www.potatopro.com/node/8764 https://www.riddhisiddhi.co.in/about.html
A4: C0041 | B4: Ingredion Incorporated | C4: Ingredion (CERELOSE®); Ingredion Pharma Solutions | D4: No | E4: Dextrose – pharma grade | F4: CERELOSE® Anhydrous Dextrose 024010 (technical specification on ingredion.com); anhydrous dextrose (US DMF via Ingredion Pharma Solutions) | G4: Anhydrous dextrose; 1 US DMF listed under 'Ingredion Pharma Solutions' (PharmaCompass; number not captured); spec sheet content not read | I4: Manufacturer | J4: pharma; food | K4: Pharma / ORS | L4: International | M4: Westchester, Illinois, USA | N4: USA | P4: https://www.ingredion.com | Q4: US DMF (PharmaCompass listing) | T4: Listed – NYSE: INGR (general knowledge) | V4: Own technical-spec PDF for CERELOSE® anhydrous dextrose surfaced in search (could not be fetched). Ingredion also owns Rafhan Maize (Pakistan) – not separately verified in this session. | W4: High | Y4: 3 | Z4: https://ingredion.com/content/dam/ingredion/technical-documents/na/CERELOSE%20Anhydrous%20Dextrose%20024010%20Technical%20Specification.pdf https://pharmacompass.com/us-drug-master-files-dmfs/anhydrous-dextrose https://pharmaoffer.com/api-excipient-supplier/company/ingredion
A5: C0072 | B5: Roquette Frères | C5: Roquette | D5: No | E5: Dextrose – pharma grade | F5: LYCADEX® PF – Dextrose monohydrate (pyrogen-free); anhydrous dextrose (US DMF listed under Roquette on PharmaCompass); dextrose datasheet for plant-care use | G5: Monohydrate, pyrogen-free (PF) grade marketed for injectables/dialysis (Roquette 'Injectable, Dialysis & Specialty APIs' range); anhydrous dextrose covered by 1 US DMF per PharmaCompass (DMF number not captured); pharmacopoeia references and feedstock not confirmed in this session | I5: Manufacturer | J5: pharma – parenteral/injectables, dialysis solutions; specialty APIs | K5: Pharma / ORS | L5: International | M5: Lestrem, Hauts-de-France, France | N5: France | O5: Lestrem, France (new injectable-carbohydrate plant per trade-press headline) | P5: https://www.roquette.com | Q5: US DMF (anhydrous dextrose) per PharmaCompass DMF listing; EDQM GMP page exists on PharmaCompass (not read) | T5: Private, family-owned group (general knowledge; not verified from a fetched page) | V5: Company's own product pages (seen as search results) name LYCADEX® PF pyrogen-free dextrose monohydrate in its injectable/dialysis range – strong fit for ORS/IV-grade needs. Grade/pharmacopoeia claims are the company's own; page content could not be fetched (rate-limited), so specs not verified. | W5: High | Y5: 5 | Z5: https://www.roquette.com/health-pharma/injectable-dialysis-specialty-apis/lycadex-pf-dextrose-monohydrate https://www.roquette.com/pharma-and-nutraceuticals-pyrogen-free-dextrose-monohydrate https://fr.roquette.com/-/media/roquette-sharepoint-libraries/marcomonline---pharma/roquette-pharma-injectable-dialysis-specialty-api-brochure.pdf https://manufacturingchemist.com/roquette-completes-injectable-carbohydrate-plant-at-lestrem-63951 https://pharmacompass.com/us-drug-master-files-dmfs/anhydrous-dextrose
A6: C0014 | B6: Cargill S.L.U. | C6: Cargill | D6: No | E6: Dextrose – pharma grade | F6: Glucose monohydrate (dextrose) – pharmaceutical grade | G6: Glucose monohydrate; Ph. Eur. CEP holder per PharmaOffer CEP listing (CEP number not captured); product origin Spain | I6: Manufacturer | J6: pharma | K6: Pharma / ORS | L6: International | M6: Spain | N6: Spain | P6: https://www.cargill.com/pharmaceutical/pharma-products/glucose-monohydrates-dextrose | Q6: CEP (glucose monohydrate), FDA, CoA – as listed on PharmaOffer (third-party listing) | T6: Subsidiary of Cargill, Incorporated (USA, private) | V6: Listed as producer with CEP for glucose monohydrate (PharmaOffer). Cargill's own pharmaceutical page for 'glucose monohydrates (dextrose)' surfaced in search but could not be fetched. Verify CEP number/validity on EDQM database. | W6: Medium | Y6: 5 | Z6: https://pharmaoffer.com/api-excipient-supplier/excipients/glucose-monohydrate/cep https://pharmaoffer.com/api-excipient-supplier/glucose-monohydrate/cep https://www.cargill.com/pharmaceutical/pharma-products/glucose-monohydrates-dextrose https://www.cargill.com/products/pharmaceutical/products/glucose-monohydrates/ https://pharmacompass.com/ndc-api/cargill-slu
A7: C0023 | B7: CSPC Shengxue Glucose Co., Ltd. | C7: CSPC Shengxue (石药圣雪) | D7: No | E7: Dextrose – pharma grade | F7: Anhydrous dextrose (US DMF holder) | G7: Anhydrous dextrose; 1 US DMF listed (PharmaCompass; number not captured) | I7: Manufacturer | J7: pharma | K7: Pharma / ORS | L7: International | M7: Hebei, China | N7: China | Q7: US DMF (PharmaCompass listing) | T7: CSPC group company (CSPC Pharmaceutical Group is HKEX-listed, 1093 – general knowledge; current shareholding not verified) | V7: US DMF holder for anhydrous dextrose per PharmaCompass. No company page fetched; capacity unknown. | W7: Medium | Y7: 3 | Z7: https://pharmacompass.com/us-drug-master-files-dmfs/anhydrous-dextrose https://www.pharmacompass.com/about/cspc-shengxue-glucose https://doc.irasia.com/listco/hk/cspc/annual/2018/screspress.pdf
A8: C0076 | B8: Shandong Tianli Pharmaceutical Co., Ltd. | C8: Tianli Pharmaceutical | D8: No | E8: Dextrose – pharma grade | F8: Anhydrous dextrose (US DMF holder) | G8: Anhydrous dextrose; 1 US DMF listed (PharmaCompass). DMF pages 37618 and 35737 surfaced in a search for this company – mapping not confirmed | I8: Manufacturer | J8: pharma | K8: Pharma / ORS | L8: International | M8: Shandong, China | N8: China | Q8: US DMF (PharmaCompass listing) | V8: Listed as US DMF holder for anhydrous dextrose. No company page fetched; verify grade (oral vs injectable) and CEP status directly. | W8: Medium | Y8: 3 | Z8: https://pharmacompass.com/us-drug-master-files-dmfs/anhydrous-dextrose https://www.pharmacompass.com/dmf-37618 https://www.pharmacompass.com/dmf-35737
A9: C0088 | B9: Tereos | C9: Tereos (Meritose) | D9: No | E9: Dextrose – pharma grade | F9: Glucose monohydrate (pharma, CEP); 'Meritose 200 Pharma' listed by distributor Quadra | G9: Glucose monohydrate with Ph. Eur. CEP per PharmaOffer (CEP number not captured); product origin France | I9: Manufacturer | J9: pharma; food | K9: Pharma / ORS | L9: International | M9: France | N9: France | P9: https://www.tereos.com | Q9: CEP, GMP, CoA – as listed on PharmaOffer (third-party listing) | V9: Listed as producer with CEP for glucose monohydrate. Link of 'Meritose' brand to Tereos is from search context, not a fetched page. Verify CEP on EDQM. | W9: Medium | Y9: 3 | Z9: https://pharmaoffer.com/api-excipient-supplier/excipients/glucose-monohydrate/cep https://pharmaoffer.com/api-excipient-supplier/company/tereos https://www.quadragroup.store/products/meritose-200-pharma-p15325
A10: C0095 | B10: Weifang Shengtai Medicine Co., Ltd. | C10: Weifang Shengtai / Shengtai Pharmaceutical | D10: No | E10: Dextrose – pharma grade | F10: Dextrose Anhydrous; Dextrose Monohydrate (CPHI-Online product listings); glucose monohydrate (CEP); anhydrous dextrose (US DMF) | G10: Anhydrous and monohydrate; Ph. Eur. CEP for glucose monohydrate (PharmaOffer); 1 US DMF for anhydrous dextrose listed as 'Weifang Shengtai Pharmaceutical' (PharmaCompass; number not captured); corn starch also produced, so maize feedstock likely (not confirmed) | H10: Glucose syrup; maltose syrup; corn starch | I10: Manufacturer | J10: pharma; food | K10: Pharma / ORS | L10: International | M10: Weifang, Shandong, China | N10: China | Q10: CEP, FDA, CoA (PharmaOffer listing); Eurofins GMP audit report dated Sep 2024 shown on PharmaOffer; US DMF (PharmaCompass) | T10: Operating company of Shengtai Pharmaceutical, Inc. (formerly US OTC: SGTI) per Yahoo Finance profile/BioSpace releases; current ownership not verified | V10: Holds both CEP and US DMF per aggregators – one of the main Chinese pharma-dextrose sources. BioSpace releases describe a new glucose facility. Company website not identified; details from CPHI-Online exhibitor listings and regulatory aggregators. | W10: Medium | Y10: 7 | Z10: https://pharmaoffer.com/api-excipient-supplier/excipients/glucose-monohydrate/cep https://pharmacompass.com/us-drug-master-files-dmfs/anhydrous-dextrose https://www.cphi-online.com/company/weifang-shengtai-medicine-co-ltd/ https://www.cphi-online.com/product/dextrose-anhydrous-3/ https://www.cphi-online.com/product/dextrose-monohydrate-4/ https://www.biospace.com/shengtai-pharmaceutical-inc-sets-up-new-sales-departments-to-accommodate-anticipated-ramp-in-operations-of-new-glucose-facility https://hk.finance.yahoo.com/quote/SGTI/profile
A11: C0097 | B11: Xiwang Pharmaceutical Co., Ltd. | C11: Xiwang Pharma | D11: No | E11: Dextrose – pharma grade | F11: Glucose monohydrate (CEP); anhydrous dextrose (US DMFs) | G11: Monohydrate with Ph. Eur. CEP (PharmaOffer); 2 US DMFs for anhydrous dextrose listed under 'XIWANG Pharmaceutical Co Ltd' (PharmaCompass; DMF 26450 surfaced in search for this company, mapping not confirmed) | I11: Manufacturer | J11: pharma | K11: Pharma / ORS | L11: International | M11: Zouping, Shandong, China | N11: China | Q11: CEP, CoA (PharmaOffer listing); US DMF x2 (PharmaCompass) | T11: Xiwang Group company (by name; not verified). HQ location from general knowledge of Xiwang Group, not a fetched page. | V11: CEP + US DMF holder per aggregators – strong candidate for pharma-grade (incl. likely injectable) dextrose from China. Company site not reached; verify CEP/DMF status directly. | W11: Medium | Y11: 4 | Z11: https://pharmaoffer.com/api-excipient-supplier/excipients/glucose-monohydrate/cep https://pharmacompass.com/us-drug-master-files-dmfs/anhydrous-dextrose https://www.pharmacompass.com/dmf-26450 https://pharmaoffer.com/api-excipient-supplier/company/xiwang-pharma
A12: C0015 | B12: Cargill, Incorporated | C12: Cargill (C*Dex) | D12: No | E12: Dextrose – food grade | F12: C*Dex™ dextrose (EMEA food & beverage); dextrose (Asia-Pacific food & beverage) | G12: Grade details not captured (pages could not be fetched) | I12: Manufacturer | J12: food; beverage | K12: Pharma / ORS | L12: International | M12: Minnesota, USA | N12: USA | P12: https://www.cargill.com | T12: Private (general knowledge) | V12: Food-grade dextrose pages on cargill.com for EMEA and Asia-Pacific surfaced in search; content not fetched. Pharma grade is covered by Cargill S.L.U. record. | W12: Medium | Y12: 2 | Z12: https://www.cargill.com/food-bev/emea/c-dex-dextrose https://www.cargill.com/food-bev/ap/dextrose
A13: C0034 | B13: Gujarat Ambuja Exports Limited | C13: GAEL / Ambuja Group | D13: Yes | E13: Dextrose – grade unspecified | F13: Dextrose Monohydrate Powder (also labelled 'Glucose Powder'); Dextrose Anhydrous Powder | G13: Monohydrate and anhydrous, powder; feedstock maize. Pharmacopoeial grade (IP/BP/USP) not shown on the starch-derivatives page. | H13: Maize starch; liquid glucose; maltodextrin; sorbitol 70% solution; pregelatinised starch; maltitol syrup; glucose syrup solids; high-maltose corn syrup; dextrose syrup | I13: Manufacturer; Processor (maize wet-miller) | J13: Food; pharma (not stated on page – verify) | K13: Pharma / ORS | L13: India-West | M13: Ahmedabad, Gujarat, India | N13: India | O13: Maize/starch units listed on company site: Dalpur, Himmatnagar (Sabarkantha, Gujarat – Bio-Chemical Division); Sitarganj (Udham Singh Nagar, Uttarakhand); Hulsoggi, Shiggaon (Haveri, Karnataka); Chalisgaon (Jalgaon, Maharashtra); Malda Industrial Growth Centre (West Bengal). Which unit makes crystalline dextrose not stated. | P13: https://www.ambujagroup.com/ | Q13: Certificates page exists on company site (contents not read) | T13: Listed (NSE: GAEL; BSE) | V13: Company's own site lists both dextrose monohydrate and dextrose anhydrous powder. Pharma grade (IP/BP/USP), pyrogen-free status and certifications not verified in this pass – request spec sheets/CoA and certificates. | W13: High | X13: Corn/Maize | Y13: 5 | Z13: https://www.ambujagroup.com/ https://www.ambujagroup.com/starch-derivatives https://www.ambujagroup.com/dextrose-anhydrous-powder https://www.ambujagroup.com/dextrose-monohydrate-powder https://www.wrightresearch.in/stocks/stock/GAEL/
A14: C0075 | B14: Sayaji Industries Limited | C14: Maize Products (Sayaji Group) | D14: Yes | E14: Dextrose – grade unspecified | F14: Dextrose Monohydrate (industry-solutions page on maizeproducts.com) | G14: Monohydrate; feedstock maize. Grade/pharmacopoeia not verified (page not opened). | H14: Maize starch and derivatives; acacia gum powder; tomato powder; fat/oil powders; cheese powder | I14: Manufacturer; Processor (maize wet-miller) | J14: Textile, food & beverage, paper, paint, pharmaceutical, confectionery industries served (Fi Global exhibitor profile) | K14: Pharma / ORS | L14: India-West | M14: Ahmedabad, Gujarat, India | N14: India | O14: Ahmedabad, Gujarat (750 MTPD maize wet-milling plant with 5 MW captive power) | P14: https://www.maizeproducts.com/ | R14: 750 MTPD maize grinding (Fi Global exhibitor profile) | T14: Listed (BSE; ISIN INE327G01032); flagship of Sayaji Group, est. 1941 | V14: Dextrose monohydrate product page exists on maizeproducts.com (seen in search results; page could not be opened due to rate limit). Fi Global profile confirms corn wet-milling and pharma customers but does not itself mention dextrose. Verify grade (IP/BP/USP) and whether crystalline dextrose is made in-house. | W14: Medium | X14: Corn/Maize | Y14: 3 | Z14: https://www.maizeproducts.com/industry-solutions/dextrose-monohydrate/ https://exhibitors.figlobal.com/net/company/26/90/94/result269094-565.html https://upstox.com/stocks/sayaji-industries-limited/INE327G01032
A15: C0094 | B15: Universal Starch-Chem Allied Limited | D15: Yes | E15: Dextrose – grade unspecified | F15: Dextrose Monohydrate (white free-flowing crystalline powder); Dextrose Syrup; Liquid Glucose Confectionery | G15: Monohydrate crystalline powder; feedstock maize (corn wet-miller). Company states food & pharmaceutical grade starch IP/BP/USP/EP – that grade statement refers to starch; dextrose pharmacopoeial grade not stated. | H15: Dextrose syrup; liquid glucose confectionery; corn starch (food/pharma IP/BP/USP/EP, paper grade); modified starches; sweeteners | I15: Manufacturer; Processor (corn wet-miller); Exporter | J15: Food; alcoholic beverages; confectionery; pharmaceuticals (per CPHI listing) | K15: Pharma / ORS | L15: India-West | M15: Dondaicha, Shindkheda, Dhule, Maharashtra, India | N15: India | O15: Shahada Road, Rawal Industrial Estate, Dada Nagar, Dondaicha, Dhule, Maharashtra | Q15: FDA, GMP, ISO 9001 (icons on company's CPHI Online profile – claimed by company) | T15: Listed company (Bloomberg ticker UNIVSTAR:IN seen in search results) | V15: CPHI Online profile (company-supplied) lists dextrose monohydrate for pharmaceutical use; exports to Mexico, East Asia and EU claimed. Pharmacopoeial grade of dextrose and injectable/pyrogen-free status not verified. 100–249 employees per CPHI. | W15: Medium | X15: Corn/Maize | Y15: 3 | Z15: https://www.cphi-online.com/company/universal-starch-chem-allied-ltd/ https://www.cphi-online.com/product/dextrose-monohydrate-3/ https://www.bloomberg.com/profile/company/UNIVSTAR:IN
A16: C0044 | B16: Jay Somnath Starch Product | D16: Yes | E16: Dextrose – grade unspecified | F16: Dextrose Anhydrous Powder; Dextrose Monohydrate Powder | G16: Anhydrous and monohydrate powder; grade not verified | I16: Manufacturer (claimed on own site; crystallisation plant not verified) | K16: Pharma / ORS | L16: India-West | M16: Rajkot, Gujarat, India | N16: India | O16: Rajkot, Gujarat (claimed) | P16: https://www.jaysomnathstarch.in/ | T16: Private firm (GSTIN 24AASFJ8076F1ZX; PAN pattern indicates a partnership firm) | V16: Own-site page titles describe the firm as manufacturer/supplier of dextrose anhydrous and monohydrate from Rajkot; pages could not be opened. A small Rajkot firm is more likely a repacker/trader than a dextrose crystalliser – verify the plant and source mill before use. Pharma grade not verified. | W16: Low | Y16: 3 | Z16: https://www.jaysomnathstarch.in/dextrose-anhydrous-powder.htm https://www.jaysomnathstarch.in/dextrose-monohydrate-powder.htm https://piceapp.com/gst-number-search/jay-somnath-starch-product-24aasfj8076f1zx/
A17: C0006 | B17: Archer-Daniels-Midland Company | C17: ADM (CLINTOSE®) | D17: No | E17: Dextrose – grade unspecified | F17: CLINTOSE® Dextrose A; CLINTOSE® Dextrose VF; ADM Dextrose Monohydrate | G17: Monohydrate listed; other grade/pharmacopoeia details not captured | I17: Manufacturer | J17: food; beverage (pharma use not verified) | K17: Pharma / ORS | L17: International | M17: Chicago, Illinois, USA | N17: USA | P17: https://www.adm.com | T17: Listed – NYSE: ADM (general knowledge) | V17: Products seen via distributor (Tilley) and Knowde ADM storefront listings; ADM's own page not fetched. Pharma grade not verified. | W17: Medium | Y17: 3 | Z17: https://www.tilleydistributionproducts.com/products/clintose-dextrose-a https://tilleydistributionproducts.com/products/clintose-dextrose-vf https://knowde.com/stores/adm/products/adm-dextrose-monohydrate
A18: C0068 | B18: Ramshree Chemicals | D18: No | E18: Dextrose – grade unspecified | F18: Dextrose Monohydrate | G18: Monohydrate; grade not verified | I18: Trader (claims manufacturer); Supplier; Exporter | K18: Not stated in sources | L18: India-Pan | M18: India (city not verified) | N18: India | P18: https://www.ramshreechemicals.in/ | V18: Own-site page title: 'Dextrose Monohydrate Manufacturer in India, Supplier, Exporter'. No plant evidence; location and legal form not verified. Treat as trader until a plant and source mill are confirmed. | W18: Low | Y18: 1 | Z18: https://www.ramshreechemicals.in/dextrose-monohydrate-3400354.html
